<?xml version="1.0"?>

<robot 
  name="chasisss"
  xmlns:sensor="http://playerstage.sourceforge.net/gazebo/xmlschema/#sensor"
xmlns:controller="http://playerstage.sourceforge.net/gazebo/xmlschema/#controller"
xmlns:interface="http://playerstage.sourceforge.net/gazebo/xmlschema/#interface"
xmlns:xacro="http://ros.org/wiki/xacro"
>

<xacro:include filename="$(find eklavya5_description)/sensors/imu.urdf.xacro" />
<xacro:include filename="$(find eklavya5_description)/sensors/gps.urdf.xacro" />
 <property name="M_PI" value="3.1415926535897931" />


  <link
    name = "base_link">
  </link>
  <link
    name="Chassis">
    <inertial>
      <origin
        xyz="0.51815 0.2035 0.46592" 
        rpy="0 0 0" />
      <mass
        value="1.60779" />
      <inertia
        ixx="0.100657"
        ixy="0.000429"
        ixz="-0.012951"
        iyy="0.062637"
        iyz="-0.000032"
        izz="0.126211" />
    </inertial>
    <visual>
      <origin
        xyz="0 0 0"
        rpy="0 0 0" />
      <geometry>
        <mesh
          filename="package://eklavya5_description/meshes/Chassis.STL" />
      </geometry>
      <material
        name="">
        <color
          rgba="0.79216 0.81961 0.93333 1" />
      </material>
    </visual>
    <collision>
      <origin
        xyz="0 0 0"
        rpy="0 0 0" />
      <geometry>
        <mesh
          filename="package://eklavya5_description/meshes/Chassis.STL" />
      </geometry>
    </collision>
  </link>
  <joint
    name="base_link-Chassis"
    type="fixed">
    <origin
      xyz="0 0 0"
      rpy="0 -1.25 -1.57" />
    <parent
      link="base_link" />
    <child
      link="Chassis" />
  </joint>
  <link
    name="Steering">
    <inertial>
      <origin
        xyz="0.074275 -0.0014324 0.24555"
        rpy="0 0 0" />
      <mass
        value="5.15679" />
      <inertia
        ixx="0.030405"
        ixy="0.00"
        ixz="-0.014212"
        iyy="0.037062"
        iyz="0.00"
        izz="0.015136" />
    </inertial>
    <visual>
      <origin
        xyz="0 0 0"
        rpy="0 0 0" />
      <geometry>
        <mesh
          filename="package://eklavya5_description/meshes/Steering.STL" />
      </geometry>
      <material
        name="">
        <color
          rgba="0.79216 0.81961 0.93333 1" />
      </material>
    </visual>
    <collision>
      <origin
        xyz="0 0 0"
        rpy="0 0 0" />
      <geometry>
        <mesh
          filename="package://eklavya5_description/meshes/Steering.STL" />
      </geometry>
    </collision>
  </link>
  <joint
    name="Chassis-Steering"
    type="revolute">
    <limit lower="${-M_PI/2.0}" upper="${M_PI/2.0}" effort="50000" velocity="10000"/>
    <origin
      xyz="0.20345 -0.10209 0.11102"
      rpy="1.2673 0 1.0548" />
    <parent
      link="Chassis" />
    <child
      link="Steering" />
    <axis
      xyz="0 0 -1" />
  
  </joint>
  <link
    name="Front Wheel">
    <inertial>
      <origin
        xyz="8.9869E-09 -1.0254E-08 -0.037497"
        rpy="0 0 0" />
      <mass
        value="7.11231" />
      <inertia
        ixx="0.084989"
        ixy="0.00"
        ixz="0.00"
        iyy="0.163706"
        iyz="0.00"
        izz="0.084989" />
    </inertial>
    <visual>
      <origin
        xyz="0 0 0"
        rpy="0 0 0" />
      <geometry>
        <mesh
          filename="package://eklavya5_description/meshes/Front Wheel.STL" />
      </geometry>
      <material
        name="">
        <color
          rgba="0.79216 0.81961 0.93333 1" />
      </material>
    </visual>
    <collision>
      <origin
        xyz="0 0 0"
        rpy="0 0 0" />
      <geometry>
        <mesh
          filename="package://eklavya5_description/meshes/Front Wheel.STL" />
      </geometry>
      <surface>
        <friction>
          <ode>
            <mu>0.5</mu>
            <mu2>0.25</mu2>
          </ode>
        </friction>
        <contact>
          <ode/>
        </contact>
     </surface>
    </collision>
  </link>
  <joint
    name="Steerring Wheel"
    type="continuous">
    <origin
      xyz="0.086603 0.038 0.087837"
      rpy="1.5708 0 3.1416" />
    <parent
      link="Steering" />
    <child
      link="Front Wheel" />
    <axis
      xyz="0 0 -1" />
    
  </joint>
  <link
    name="Left Wheel">
    <inertial>
      <origin
        xyz="4.0523E-15 0.057678 2.2204E-16"
        rpy="0 0 0" />
      <mass
        value="6.50284" />
      <inertia
        ixx="0.084208"
        ixy="0.00"
        ixz="0.00"
        iyy="0.161025"
        iyz="0.00"
        izz="0.084208" />
    </inertial>
    <visual>
      <origin
        xyz="0 0 0"
        rpy="0 0 0" />
      <geometry>
        <mesh
          filename="package://eklavya5_description/meshes/Left Wheel.STL" />
      </geometry>
      <material
        name="">
        <color
          rgba="0.79216 0.81961 0.93333 1" />
      </material>
    </visual>
    <collision>
      <origin
        xyz="0 0 0"
        rpy="0 0 0" />
      <geometry>
        <mesh
          filename="package://eklavya5_description/meshes/Left Wheel.STL" />
      </geometry>
      <surface>
        <friction>
          <ode>
            <mu>0.5</mu>
            <mu2>0.25</mu2>
          </ode>
        </friction>
        <contact>
          <ode/>
        </contact>
     </surface>      
     
    </collision>
  </link>
  <joint
    name="LW-Chassis"
    type="continuous">
    <origin
      xyz="0.23345 -0.80043 0.41447"
      rpy="1.4533 -0.25456 0.43831" />
    <parent
      link="Chassis" />
    <child
      link="Left Wheel" />
    <axis
      xyz="0 -1 0" />
    
  </joint>
  <link
    name="Right Wheel">
    <inertial>
      <origin
        xyz="-1.0103E-14 1.8874E-15 0.073368"
        rpy="0 0 0" />
      <mass
        value="6.50284" />
      <inertia
        ixx="0.084208"
        ixy="0.00"
        ixz="0.00"
        iyy="0.161025"
        iyz="0.00"
        izz="0.084208" />
    </inertial>
    <visual>
      <origin
        xyz="0 0 0"
        rpy="0 0 0" />
      <geometry>
        <mesh
          filename="package://eklavya5_description/meshes/Right Wheel.STL" />
      </geometry>
      <material
        name="">
        <color
          rgba="0.79216 0.81961 0.93333 1" />
      </material>
    </visual>
    <collision>
      <origin
        xyz="0 0 0"
        rpy="0 0 0" />
      <geometry>
        <mesh
          filename="package://eklavya5_description/meshes/Right Wheel.STL" />
      </geometry>
      <surface>
        <friction>
          <ode>
            <mu>0.5</mu>
            <mu2>0.25</mu2>
          </ode>
        </friction>
        <contact>
          <ode/>
        </contact>
     </surface>
    </collision>
  </link>
  <joint
    name="RW-Chassis"
    type="continuous">
    <origin
      xyz="0.384 -0.80043 -0.10941"
      rpy="-3.0808 -0.27332 -0.22183" />
    <parent
      link="Chassis" />
    <child
      link="Right Wheel" />
    <axis
      xyz="0 0 1" />
   
  </joint>

  <joint name="camera_joint" type="fixed">
    <axis xyz="0 1 0" />
    <origin xyz="0.05 0 0.5" rpy="0 0 0"/>
    <parent link="Steering"/>
    <child link="camera_link"/>
  </joint>

  <!-- Camera -->
  <link name="camera_link">
    <collision>
      <origin xyz="0 0 0" rpy="0 0 0"/>
      <geometry>
    <box size="0.05 0.05 0.05"/>
      </geometry>
    </collision>

    <visual>
      <origin xyz="0 0 0" rpy="0 0 0"/>
      <geometry>
<box size="0.05 0.05 0.05"/>
      </geometry>
      <material name="red"/>
    </visual>

    <inertial>
      <mass value="1e-5" />
      <origin xyz="0 0 0" rpy="0 0 0"/>
      <inertia ixx="1e-6" ixy="0" ixz="0" iyy="1e-6" iyz="0" izz="1e-6" />
    </inertial> 
  </link>

  <gazebo reference="camera_link">
    <sensor type="camera" name="camera1">
      <update_rate>24.0</update_rate>
      <camera name="head">
        <horizontal_fov>1.23</horizontal_fov>
        <image>
          <width>640</width>
          <height>480</height>
          <format>R8G8B8</format>
        </image>
        <clip>
          <near>0.02</near>
          <far>300</far>
        </clip>
        <noise>
          <type>gaussian</type>
          <!-- Noise is sampled independently per pixel on each frame.
               That pixel's noise value is added to each of its color
               channels, which at that point lie in the range [0,1]. -->
          <mean>0.0</mean>
          <stddev>0.007</stddev>
        </noise>
      </camera>
      <plugin name="camera_controller" filename="libgazebo_ros_camera.so">
        <alwaysOn>true</alwaysOn>
        <updateRate>0.0</updateRate>
        <cameraName>eklavya</cameraName>
        <imageTopicName>image_raw</imageTopicName>
        <cameraInfoTopicName>camera_info</cameraInfoTopicName>
        <frameName>camera_link</frameName>
        <hackBaseline>0.07</hackBaseline>
        <distortionK1>0.0</distortionK1>
        <distortionK2>0.0</distortionK2>
        <distortionK3>0.0</distortionK3>
        <distortionT1>0.0</distortionT1>
        <distortionT2>0.0</distortionT2>
      </plugin>
    </sensor>
  </gazebo>

<!-- Hokuyo Laser-->
<joint name="hokuyo_joint" type="fixed">
    <axis xyz="0 1 0" />
    <origin xyz="-0.2 0 0.8" rpy="0 0 0"/>
    <parent link="base_link"/>
    <child link="hokuyo_link"/>
  </joint>


  <link name="hokuyo_link">
    <collision>
      <origin xyz="0 0 0" rpy="0 0 0"/>
      <geometry>
    <box size="0.025 0.025 0.025"/>
      </geometry>
    </collision>

    <visual>
      <origin xyz="0 0 0" rpy="0 0 0"/>
      <geometry>
        <mesh filename="package://eklavya5_description/meshes/hokuyo.dae"/>
      </geometry>
    </visual>

    <inertial>
      <mass value="1e-5" />
      <origin xyz="0 0 0" rpy="0 0 0"/>
      <inertia ixx="1e-6" ixy="0" ixz="0" iyy="1e-6" iyz="0" izz="1e-6" />
    </inertial>
  </link>
  <!-- hokuyo -->
  <gazebo reference="hokuyo_link">
    <sensor type="ray" name="head_hokuyo_sensor">
      <pose>0 0 0 0 0 0</pose>
      <visualize>true</visualize>
      <update_rate>40</update_rate>
      <ray>
        <scan>
          <horizontal>
            <samples>720</samples>
            <resolution>1</resolution>
            <min_angle>-1.570796</min_angle>
            <max_angle>1.570796</max_angle>
          </horizontal>
        </scan>
        <range>
          <min>0.1</min>
          <max>40.0</max>
          <resolution>0.01</resolution>
        </range>
        <noise>
          <type>gaussian</type>
          <!-- Noise parameters based on published spec for Hokuyo laser
               achieving "+-30mm" accuracy at range < 10m.  A mean of 0.0m and
               stddev of 0.01m will put 99.7% of samples within 0.03m of the true
               reading. -->
          <mean>0.0</mean>
          <stddev>0.01</stddev>
        </noise>
      </ray>
      <plugin name="gazebo_ros_head_hokuyo_controller" filename="libgazebo_ros_laser.so">
        <topicName>eklavya/laser/scan</topicName>
        <frameName>hokuyo_link</frameName>
      </plugin>
    </sensor>
  </gazebo>



<!-- IMU-->

    <sensor_imu parent="base_link" name="imu" colour="Blue" imu_px="-1" imu_py="0.0" imu_pz="0.8" imu_or="0.0" imu_op="${-M_PI/2.0}" imu_oy="0.0">
      
    </sensor_imu>

    <gazebo reference="imu_link">
        <material>Gazebo/Blue</material>
    </gazebo>

    
 
    <!-- GPS antenna/module -->
    <sensor_gps parent="base_link" name="gps"
          colour="White"

          gps_px="-0.8" 
          gps_py="0" 
          gps_pz="0.8" 
          gps_or="0.0" 
          gps_op="0.0" 
          gps_oy="${M_PI}" 
          dimX="0.16" dimY="0.16" dimZ="0.14"
          >
      
    </sensor_gps>
    <gazebo reference="gps_link">
        <material>Gazebo/White</material>
    </gazebo>
    <!--<transmission type="SimpleTransmission" name="FrontWheel">
      <type>transmission_interface/SimpleTransmission</type>
      <joint name="Steerring Wheel" />
      <actuator name="Steering_wheel_joint_motor">
        <hardwareInterface>EffortJointInterface</hardwareInterface>
        <mechanicalReduction>1</mechanicalReduction>
      </actuator>
  </transmission>
  <transmission type="SimpleTransmission" name="LeftWheel">
      <type>transmission_interface/SimpleTransmission</type>
      <joint name="LW-Chassis" />
      <actuator name="Left_wheel_joint_motor">
        <hardwareInterface>EffortJointInterface</hardwareInterface>
        <mechanicalReduction>1</mechanicalReduction>
      </actuator>
  </transmission>
  <transmission type="SimpleTransmission" name="RightWheel">
      <type>transmission_interface/SimpleTransmission</type>
      <joint name="RW-Chassis" />
      <actuator name="Right_wheel_joint_motor">
        <hardwareInterface>EffortJointInterface</hardwareInterface>
        <mechanicalReduction>1</mechanicalReduction>
      </actuator>
  </transmission>-->
    <!-- Controls plugin-->
  <gazebo>
    <plugin filename="libeklavya_gazebo_plugins.so" name="eklavya_diff_controller">
-      <alwaysOn>true</alwaysOn>
-      <updateRate>100.0</updateRate>
-      <backLeftJoint>joint_back_left_wheel</backLeftJoint>
-      <backRightJoint>joint_back_right_wheel</backRightJoint>
-      <frontLeftJoint>joint_front_left_wheel</frontLeftJoint>
-      <!--<frontRightJoint>joint_front_right_wheel</frontRightJoint>-->
-      <wheelSeparation>0.5709</wheelSeparation>
-      <wheelDiameter>0.3555</wheelDiameter>
-      <torque>35</torque>
-    </plugin>
     <!--<plugin name="gazebo_ros_control" filename="libgazebo_ros_control.so" />-->
  </gazebo>
-  <!--
-  <gazebo>
-    <plugin filename="libgazebo_ros_p3d.so" name="eklavya_groundtruth_sim">
-      <updateRate>100.0</updateRate>
-      <topicName>ground_truth/odom</topicName>
-      <gaussianNoise>0.001</gaussianNoise>
-      <frameName>world</frameName>
-      <alwaysOn>true</alwaysOn>
-      <bodyName>base_footprint</bodyName>
-      <xyzOffset>0 0 0</xyzOffset>
-      <rpyOffset>0 0 0</rpyOffset>
-    </plugin>
   </gazebo>-->
  
</robot>
